Workbook
Name TR一覧: #REF!
Name TR一覧: #REF!
Name TR一覧: #REF!
Name TR一覧: #REF!
Name TR結線一覧: #REF!
Name TR結線一覧: #REF!
Name TR結線一覧: #REF!
Name TR結線一覧: #REF!
Name TR容量一覧: #REF!
Name TR容量一覧: #REF!
Name TR容量一覧: #REF!
Name TR容量一覧: #REF!
Name 一次側電圧一覧: #REF!
Name 一次側電圧一覧: #REF!
Name 一次側電圧一覧: #REF!
Name 一次側電圧一覧: #REF!
Name 回路分類一覧: #REF!
Name 回路分類一覧: #REF!
Name 回路分類一覧: #REF!
Name 回路分類一覧: #REF!
Name 受電接続負荷種別: #REF!
Name 受電接続負荷種別: #REF!
Name 受電接続負荷種別: #REF!
Name 受電接続負荷種別: #REF!
Name 需要家受電電圧: #REF!
Name 需要家受電電圧: #REF!
Name 需要家受電電圧: #REF!
Name 需要家受電電圧: #REF!
Name 需要家受電方式: #REF!
Name 需要家受電方式: #REF!
Name 需要家受電方式: #REF!
Name 需要家受電方式: #REF!
Name 設備種類: #REF!
Name 設備種類: #REF!
Name 設備種類: #REF!
Name 設備種類: #REF!
Name 電力会社: #REF!
Name 電力会社: #REF!
Name 電力会社: #REF!
Name 電力会社: #REF!
Name 二次側電圧一覧: #REF!
Name 二次側電圧一覧: #REF!
Name 二次側電圧一覧: #REF!
Name 二次側電圧一覧: #REF!
Name 入力TR一覧: #REF!
Name 入力TR一覧: #REF!
Name 入力TR一覧: #REF!
Name 入力TR一覧: #REF!
Name 負荷種別: #REF!
Name 負荷種別: #REF!
Name 負荷種別: #REF!
Name 負荷種別: #REF!

Sheet 様式５の３
T1: 様式５の３
M3: ※用紙の大きさは、日本工業規格Ａ３サイズまたはＡ４サイズとしてください。
S4: =#REF! -> #REF!
P5: 発電設備等設置者名 | R5: =#REF! -> #REF!
A6: 設 備 運 用 方 法
A7: － 発電機運転パターン、受電地点における受電電力パターン －

Sheet （日負荷曲線用需要データ）
C2: 0.020833333 | D2: 0.041666667 | E2: 0.0625 | F2: 0.083333333 | G2: 0.10416667 | H2: 0.125 | I2: 0.14583333 | J2: 0.16666667 | K2: 0.1875 | L2: 0.20833333 | M2: 0.22916667 | N2: 0.25 | O2: 0.27083333 | P2: 0.29166667 | Q2: 0.3125 | R2: 0.33333333 | S2: 0.35416667 | T2: 0.375 | U2: 0.39583333 | V2: 0.41666667 | W2: 0.4375 | X2: 0.45833333 | Y2: 0.47916667 | Z2: 0.5 | AA2: 0.52083333 | AB2: 0.54166667 | AC2: 0.5625 | AD2: 0.58333333 | AE2: 0.60416667 | AF2: 0.625 | AG2: 0.64583333 | AH2: 0.66666667 | AI2: 0.6875 | AJ2: 0.70833333 | AK2: 0.72916667 | AL2: 0.75 | AM2: 0.77083333 | AN2: 0.79166667 | AO2: 0.8125 | AP2: 0.83333333 | AQ2: 0.85416667 | AR2: 0.875 | AS2: 0.89583333 | AT2: 0.91666667 | AU2: 0.9375 | AV2: 0.95833333 | AW2: 0.97916667 | AX2: 1
A3: 冬 | B3: 11月 | C3: ='（日負荷曲線用元データ）'!B33 -> 58 | D3: ='（日負荷曲線用元データ）'!C33 -> 42 | E3: ='（日負荷曲線用元データ）'!D33 -> 41 | F3: ='（日負荷曲線用元データ）'!E33 -> 39 | G3: ='（日負荷曲線用元データ）'!F33 -> 39 | H3: ='（日負荷曲線用元データ）'!G33 -> 42 | I3: ='（日負荷曲線用元データ）'!H33 -> 41 | J3: ='（日負荷曲線用元データ）'!I33 -> 39 | ... AX3: ='（日負荷曲線用元データ）'!AW33 -> 92.068966
A4: 冬 | B4: 12月 | C4: ='（日負荷曲線用元データ）'!B66 -> 56.5 | D4: ='（日負荷曲線用元データ）'!C66 -> 41.071429 | E4: ='（日負荷曲線用元データ）'!D66 -> 39.035714 | F4: ='（日負荷曲線用元データ）'!E66 -> 35.214286 | G4: ='（日負荷曲線用元データ）'!F66 -> 36.071429 | H4: ='（日負荷曲線用元データ）'!G66 -> 39 | I4: ='（日負荷曲線用元データ）'!H66 -> 38.607143 | J4: ='（日負荷曲線用元データ）'!I66 -> 36.535714 | ... AX4: ='（日負荷曲線用元データ）'!AW66 -> 84.548387
A5: 冬 | B5: 1月 | C5: ='（日負荷曲線用元データ）'!B99 -> 54.193548 | D5: ='（日負荷曲線用元データ）'!C99 -> 40.612903 | E5: ='（日負荷曲線用元データ）'!D99 -> 38.548387 | F5: ='（日負荷曲線用元データ）'!E99 -> 34.870968 | G5: ='（日負荷曲線用元データ）'!F99 -> 36.225806 | H5: ='（日負荷曲線用元データ）'!G99 -> 38.387097 | I5: ='（日負荷曲線用元データ）'!H99 -> 36.83871 | J5: ='（日負荷曲線用元データ）'!I99 -> 35.354839 | ... AX5: ='（日負荷曲線用元データ）'!AW99 -> 78.870968
A6: 冬 | B6: 2月 | C6: ='（日負荷曲線用元データ）'!B130 -> 53.75 | D6: ='（日負荷曲線用元データ）'!C130 -> 38.5 | E6: ='（日負荷曲線用元データ）'!D130 -> 36.607143 | F6: ='（日負荷曲線用元データ）'!E130 -> 32.678571 | G6: ='（日負荷曲線用元データ）'!F130 -> 33.642857 | H6: ='（日負荷曲線用元データ）'!G130 -> 36.107143 | I6: ='（日負荷曲線用元データ）'!H130 -> 34.928571 | J6: ='（日負荷曲線用元データ）'!I130 -> 32.75 | ... AX6: ='（日負荷曲線用元データ）'!AW130 -> 83.928571
A7: 冬 | B7: 3月 | C7: ='（日負荷曲線用元データ）'!B163 -> 58.354839 | D7: ='（日負荷曲線用元データ）'!C163 -> 40.741935 | E7: ='（日負荷曲線用元データ）'!D163 -> 39.612903 | F7: ='（日負荷曲線用元データ）'!E163 -> 36.290323 | G7: ='（日負荷曲線用元データ）'!F163 -> 37.290323 | H7: ='（日負荷曲線用元データ）'!G163 -> 40.258065 | I7: ='（日負荷曲線用元データ）'!H163 -> 38.83871 | J7: ='（日負荷曲線用元データ）'!I163 -> 36.677419 | ... AX7: ='（日負荷曲線用元データ）'!AW163 -> 86.580645
B8: 平均 | C8: =AVERAGE(C3:D7) -> 48.372465 | E8: =AVERAGE(E3:F7) -> 37.285829 | G8: =AVERAGE(G3:H7) -> 37.798272 | I8: =AVERAGE(I3:J7) -> 37.053111 | K8: =AVERAGE(K3:L7) -> 34.096429 | M8: =AVERAGE(M3:N7) -> 45.306682 | O8: =AVERAGE(O3:P7) -> 93.087558 | Q8: =AVERAGE(Q3:R7) -> 104.97707 | S8: =AVERAGE(S3:T7) -> 113.82097 | U8: =AVERAGE(U3:V7) -> 122.42915 | W8: =AVERAGE(W3:X7) -> 117.96221 | Y8: =AVERAGE(Y3:Z7) -> 118.87972 | AA8: =AVERAGE(AA3:AB7) -> 120.65691 | AC8: =AVERAGE(AC3:AD7) -> 118.37051 | AE8: =AVERAGE(AE3:AF7) -> 116.97293 | AG8: =AVERAGE(AG3:AH7) -> 114.56166 | AI8: =AVERAGE(AI3:AJ7) -> 109.18311 | AK8: =AVERAGE(AK3:AL7) -> 107.38915 | AM8: =AVERAGE(AM3:AN7) -> 107.03634 | AO8: =AVERAGE(AO3:AP7) -> 105.21935 | AQ8: =AVERAGE(AQ3:AR7) -> 102.404 | AS8: =AVERAGE(AS3:AT7) -> 97.358525 | AU8: =AVERAGE(AU3:AV7) -> 90.401108 | AW8: =AVERAGE(AW3:AX7) -> 86.740366
C9: =(SUM(C4+D4)+SUM(C5+D5)+SUM(C6+D6)+SUM(C7+D7)+SUM(C3+D3))/5 -> 96.744931 | E9: =(SUM(E4+F4)+SUM(E5+F5)+SUM(E6+F6)+SUM(E7+F7)+SUM(E3+F3))/5 -> 74.571659 | G9: =(SUM(G4+H4)+SUM(G5+H5)+SUM(G6+H6)+SUM(G7+H7)+SUM(G3+H3))/5 -> 75.596544 | I9: =(SUM(I4+J4)+SUM(I5+J5)+SUM(I6+J6)+SUM(I7+J7)+SUM(I3+J3))/5 -> 74.106221 | K9: =(SUM(K4+L4)+SUM(K5+L5)+SUM(K6+L6)+SUM(K7+L7)+SUM(K3+L3))/5 -> 68.192857 | M9: =(SUM(M4+N4)+SUM(M5+N5)+SUM(M6+N6)+SUM(M7+N7)+SUM(M3+N3))/5 -> 90.613364 | O9: =(SUM(O4+P4)+SUM(O5+P5)+SUM(O6+P6)+SUM(O7+P7)+SUM(O3+P3))/5 -> 186.17512 | Q9: =(SUM(Q4+R4)+SUM(Q5+R5)+SUM(Q6+R6)+SUM(Q7+R7)+SUM(Q3+R3))/5 -> 209.95415 | S9: =(SUM(S4+T4)+SUM(S5+T5)+SUM(S6+T6)+SUM(S7+T7)+SUM(S3+T3))/5 -> 227.64194 | U9: =(SUM(U4+V4)+SUM(U5+V5)+SUM(U6+V6)+SUM(U7+V7)+SUM(U3+V3))/5 -> 244.85829 | W9: =(SUM(W4+X4)+SUM(W5+X5)+SUM(W6+X6)+SUM(W7+X7)+SUM(W3+X3))/5 -> 235.92442 | Y9: =(SUM(Y4+Z4)+SUM(Y5+Z5)+SUM(Y6+Z6)+SUM(Y7+Z7)+SUM(Y3+Z3))/5 -> 237.75945 | AA9: =(SUM(AA4+AB4)+SUM(AA5+AB5)+SUM(AA6+AB6)+SUM(AA7+AB7)+SUM(AA3+AB3))/5 -> 241.31382 | AC9: =(SUM(AC4+AD4)+SUM(AC5+AD5)+SUM(AC6+AD6)+SUM(AC7+AD7)+SUM(AC3+AD3))/5 -> 236.74101 | AE9: =(SUM(AE4+AF4)+SUM(AE5+AF5)+SUM(AE6+AF6)+SUM(AE7+AF7)+SUM(AE3+AF3))/5 -> 233.94585 | AG9: =(SUM(AG4+AH4)+SUM(AG5+AH5)+SUM(AG6+AH6)+SUM(AG7+AH7)+SUM(AG3+AH3))/5 -> 229.12333 | AI9: =(SUM(AI4+AJ4)+SUM(AI5+AJ5)+SUM(AI6+AJ6)+SUM(AI7+AJ7)+SUM(AI3+AJ3))/5 -> 218.36622 | AK9: =(SUM(AK4+AL4)+SUM(AK5+AL5)+SUM(AK6+AL6)+SUM(AK7+AL7)+SUM(AK3+AL3))/5 -> 214.77829 | AM9: =(SUM(AM4+AN4)+SUM(AM5+AN5)+SUM(AM6+AN6)+SUM(AM7+AN7)+SUM(AM3+AN3))/5 -> 214.07268 | AO9: =(SUM(AO4+AP4)+SUM(AO5+AP5)+SUM(AO6+AP6)+SUM(AO7+AP7)+SUM(AO3+AP3))/5 -> 210.43869 | AQ9: =(SUM(AQ4+AR4)+SUM(AQ5+AR5)+SUM(AQ6+AR6)+SUM(AQ7+AR7)+SUM(AQ3+AR3))/5 -> 204.80801 | AS9: =(SUM(AS4+AT4)+SUM(AS5+AT5)+SUM(AS6+AT6)+SUM(AS7+AT7)+SUM(AS3+AT3))/5 -> 194.71705 | AU9: =(SUM(AU4+AV4)+SUM(AU5+AV5)+SUM(AU6+AV6)+SUM(AU7+AV7)+SUM(AU3+AV3))/5 -> 180.80222 | AW9: =(SUM(AW4+AX4)+SUM(AW5+AX5)+SUM(AW6+AX6)+SUM(AW7+AX7)+SUM(AW3+AX3))/5 -> 173.48073
A10: 春 | B10: 4月 | C10: ='（日負荷曲線用元データ）'!B195 -> 59.662851 | D10: ='（日負荷曲線用元データ）'!C195 -> 41.5 | E10: ='（日負荷曲線用元データ）'!D195 -> 39.804891 | F10: ='（日負荷曲線用元データ）'!E195 -> 37.033333 | G10: ='（日負荷曲線用元データ）'!F195 -> 37.218522 | H10: ='（日負荷曲線用元データ）'!G195 -> 40.533333 | I10: ='（日負荷曲線用元データ）'!H195 -> 39.959938 | J10: ='（日負荷曲線用元データ）'!I195 -> 37.633333 | ... AX10: ='（日負荷曲線用元データ）'!AW195 -> 85.066667
A11: 春 | B11: 5月 | C11: ='（日負荷曲線用元データ）'!B228 -> 65.032258 | D11: ='（日負荷曲線用元データ）'!C228 -> 48.096774 | E11: ='（日負荷曲線用元データ）'!D228 -> 47.903226 | F11: ='（日負荷曲線用元データ）'!E228 -> 45.096774 | G11: ='（日負荷曲線用元データ）'!F228 -> 44.129032 | H11: ='（日負荷曲線用元データ）'!G228 -> 49.225806 | I11: ='（日負荷曲線用元データ）'!H228 -> 48.096774 | J11: ='（日負荷曲線用元データ）'!I228 -> 46.258065 | ... AX11: ='（日負荷曲線用元データ）'!AW228 -> 85.870968
A12: 秋 | B12: 9月 | C12: ='（日負荷曲線用元データ）'!B358 -> 77.90841 | D12: ='（日負荷曲線用元データ）'!C358 -> 61.766667 | E12: ='（日負荷曲線用元データ）'!D358 -> 62.332373 | F12: ='（日負荷曲線用元データ）'!E358 -> 59.9 | G12: ='（日負荷曲線用元データ）'!F358 -> 56.396313 | H12: ='（日負荷曲線用元データ）'!G358 -> 64.5 | I12: ='（日負荷曲線用元データ）'!H358 -> 63.342742 | J12: ='（日負荷曲線用元データ）'!I358 -> 61.966667 | ... AX12: ='（日負荷曲線用元データ）'!AW358 -> 105.53333
A13: 秋 | B13: 10月 | C13: ='（日負荷曲線用元データ）'!B391 -> 65.419355 | D13: ='（日負荷曲線用元データ）'!C391 -> 47.483871 | E13: ='（日負荷曲線用元データ）'!D391 -> 46.903226 | F13: ='（日負荷曲線用元データ）'!E391 -> 43.967742 | G13: ='（日負荷曲線用元データ）'!F391 -> 43.064516 | H13: ='（日負荷曲線用元データ）'!G391 -> 48.451613 | I13: ='（日負荷曲線用元データ）'!H391 -> 46.290323 | J13: ='（日負荷曲線用元データ）'!I391 -> 45.225806 | ... AX13: ='（日負荷曲線用元データ）'!AW391 -> 95.967742
B14: 平均 | C14: =AVERAGE(C10:D13) -> 58.358773 | E14: =AVERAGE(E10:F13) -> 47.867696 | G14: =AVERAGE(G10:H13) -> 47.939892 | I14: =AVERAGE(I10:J13) -> 48.596706 | K14: =AVERAGE(K10:L13) -> 44.69154 | M14: =AVERAGE(M10:N13) -> 53.597351 | O14: =AVERAGE(O10:P13) -> 94.515815 | Q14: =AVERAGE(Q10:R13) -> 109.32914 | S14: =AVERAGE(S10:T13) -> 122.12149 | U14: =AVERAGE(U10:V13) -> 133.93562 | W14: =AVERAGE(W10:X13) -> 130.00263 | Y14: =AVERAGE(Y10:Z13) -> 132.52291 | AA14: =AVERAGE(AA10:AB13) -> 132.32792 | AC14: =AVERAGE(AC10:AD13) -> 132.19725 | AE14: =AVERAGE(AE10:AF13) -> 129.79135 | AG14: =AVERAGE(AG10:AH13) -> 128.95124 | AI14: =AVERAGE(AI10:AJ13) -> 121.05941 | AK14: =AVERAGE(AK10:AL13) -> 117.55218 | AM14: =AVERAGE(AM10:AN13) -> 112.8221 | AO14: =AVERAGE(AO10:AP13) -> 110.91276 | AQ14: =AVERAGE(AQ10:AR13) -> 108.35806 | AS14: =AVERAGE(AS10:AT13) -> 106.13613 | AU14: =AVERAGE(AU10:AV13) -> 98.57529 | AW14: =AVERAGE(AW10:AX13) -> 94.314399
C15: =(SUM(C10+D10)+SUM(C11+D12)+SUM(C12+D11)+SUM(D13+C13))/4 -> 116.71755 | E15: =(SUM(E10+F10)+SUM(E11+F12)+SUM(E12+F11)+SUM(F13+E13))/4 -> 95.735391 | G15: =(SUM(G10+H10)+SUM(G11+H12)+SUM(G12+H11)+SUM(H13+G13))/4 -> 95.879784 | I15: =(SUM(I10+J10)+SUM(I11+J12)+SUM(I12+J11)+SUM(J13+I13))/4 -> 97.193412 | K15: =(SUM(K10+L10)+SUM(K11+L12)+SUM(K12+L11)+SUM(L13+K13))/4 -> 89.383079 | M15: =(SUM(M10+N10)+SUM(M11+N12)+SUM(M12+N11)+SUM(N13+M13))/4 -> 107.1947 | O15: =(SUM(O10+P10)+SUM(O11+P12)+SUM(O12+P11)+SUM(P13+O13))/4 -> 189.03163 | Q15: =(SUM(Q10+R10)+SUM(Q11+R12)+SUM(Q12+R11)+SUM(R13+Q13))/4 -> 218.65828 | S15: =(SUM(S10+T10)+SUM(S11+T12)+SUM(S12+T11)+SUM(T13+S13))/4 -> 244.24297 | U15: =(SUM(U10+V10)+SUM(U11+V12)+SUM(U12+V11)+SUM(V13+U13))/4 -> 267.87124 | W15: =(SUM(W10+X10)+SUM(W11+X12)+SUM(W12+X11)+SUM(X13+W13))/4 -> 260.00527 | Y15: =(SUM(Y10+Z10)+SUM(Y11+Z12)+SUM(Y12+Z11)+SUM(Z13+Y13))/4 -> 265.04583 | AA15: =(SUM(AA10+AB10)+SUM(AA11+AB12)+SUM(AA12+AB11)+SUM(AB13+AA13))/4 -> 264.65583 | AC15: =(SUM(AC10+AD10)+SUM(AC11+AD12)+SUM(AC12+AD11)+SUM(AD13+AC13))/4 -> 264.39449 | AE15: =(SUM(AE10+AF10)+SUM(AE11+AF12)+SUM(AE12+AF11)+SUM(AF13+AE13))/4 -> 259.58269 | AG15: =(SUM(AG10+AH10)+SUM(AG11+AH12)+SUM(AG12+AH11)+SUM(AH13+AG13))/4 -> 257.90247 | AI15: =(SUM(AI10+AJ10)+SUM(AI11+AJ12)+SUM(AI12+AJ11)+SUM(AJ13+AI13))/4 -> 242.11882 | AK15: =(SUM(AK10+AL10)+SUM(AK11+AL12)+SUM(AK12+AL11)+SUM(AL13+AK13))/4 -> 235.10436 | AM15: =(SUM(AM10+AN10)+SUM(AM11+AN12)+SUM(AM12+AN11)+SUM(AN13+AM13))/4 -> 225.64421 | AO15: =(SUM(AO10+AP10)+SUM(AO11+AP12)+SUM(AO12+AP11)+SUM(AP13+AO13))/4 -> 221.82552 | AQ15: =(SUM(AQ10+AR10)+SUM(AQ11+AR12)+SUM(AQ12+AR11)+SUM(AR13+AQ13))/4 -> 216.71613 | AS15: =(SUM(AS10+AT10)+SUM(AS11+AT12)+SUM(AS12+AT11)+SUM(AT13+AS13))/4 -> 212.27226 | AU15: =(SUM(AU10+AV10)+SUM(AU11+AV12)+SUM(AU12+AV11)+SUM(AV13+AU13))/4 -> 197.15058 | AW15: =(SUM(AW10+AX10)+SUM(AW11+AX12)+SUM(AW12+AX11)+SUM(AX13+AW13))/4 -> 188.6288
A16: 夏 | B16: 6月 | C16: ='（日負荷曲線用元データ）'!B260 -> 70.244017 | D16: ='（日負荷曲線用元データ）'!C260 -> 53.066667 | E16: ='（日負荷曲線用元データ）'!D260 -> 52.66129 | F16: ='（日負荷曲線用元データ）'!E260 -> 49.633333 | G16: ='（日負荷曲線用元データ）'!F260 -> 47.312175 | H16: ='（日負荷曲線用元データ）'!G260 -> 53.466667 | I16: ='（日負荷曲線用元データ）'!H260 -> 51.973465 | J16: ='（日負荷曲線用元データ）'!I260 -> 50.9 | ... AX16: ='（日負荷曲線用元データ）'!AW260 -> 95.7
A17: 夏 | B17: 7月 | C17: ='（日負荷曲線用元データ）'!B293 -> 75.677419 | D17: ='（日負荷曲線用元データ）'!C293 -> 58.741935 | E17: ='（日負荷曲線用元データ）'!D293 -> 58.096774 | F17: ='（日負荷曲線用元データ）'!E293 -> 55.16129 | G17: ='（日負荷曲線用元データ）'!F293 -> 51.677419 | H17: ='（日負荷曲線用元データ）'!G293 -> 59.322581 | I17: ='（日負荷曲線用元データ）'!H293 -> 57.483871 | J17: ='（日負荷曲線用元データ）'!I293 -> 56.322581 | ... AX17: ='（日負荷曲線用元データ）'!AW293 -> 103.16129
A18: 夏 | B18: 8月 | C18: ='（日負荷曲線用元データ）'!B326 -> 83.428571 | D18: ='（日負荷曲線用元データ）'!C326 -> 66.892857 | E18: ='（日負荷曲線用元データ）'!D326 -> 66.678571 | F18: ='（日負荷曲線用元データ）'!E326 -> 63.928571 | G18: ='（日負荷曲線用元データ）'!F326 -> 58.928571 | H18: ='（日負荷曲線用元データ）'!G326 -> 67.642857 | I18: ='（日負荷曲線用元データ）'!H326 -> 66 | J18: ='（日負荷曲線用元データ）'!I326 -> 65.25 | ... AX18: ='（日負荷曲線用元データ）'!AW326 -> 116.67742
B19: 平均
C20: =(SUM(C16+D16)+SUM(C17+D17)+SUM(C18+D18))/3 -> 136.01716 | E20: =(SUM(E16+F16)+SUM(E17+F17)+SUM(E18+F18))/3 -> 115.38661 | G20: =(SUM(G16+H16)+SUM(G17+H17)+SUM(G18+H18))/3 -> 112.78342 | I20: =(SUM(I16+J16)+SUM(I17+J17)+SUM(I18+J18))/3 -> 115.97664 | K20: =(SUM(K16+L16)+SUM(K17+L17)+SUM(K18+L18))/3 -> 109.00527 | M20: =(SUM(M16+N16)+SUM(M17+N17)+SUM(M18+N18))/3 -> 132.93771 | O20: =(SUM(O16+P16)+SUM(O17+P17)+SUM(O18+P18))/3 -> 202.80104 | Q20: =(SUM(Q16+R16)+SUM(Q17+R17)+SUM(Q18+R18))/3 -> 244.79783 | S20: =(SUM(S16+T16)+SUM(S17+T17)+SUM(S18+T18))/3 -> 278.46876 | U20: =(SUM(U16+V16)+SUM(U17+V17)+SUM(U18+V18))/3 -> 312.32368 | W20: =(SUM(W16+X16)+SUM(W17+X17)+SUM(W18+X18))/3 -> 307.43881 | Y20: =(SUM(Y16+Z16)+SUM(Y17+Z17)+SUM(Y18+Z18))/3 -> 314.21242 | AA20: =(SUM(AA16+AB16)+SUM(AA17+AB17)+SUM(AA18+AB18))/3 -> 311.72797 | AC20: =(SUM(AC16+AD16)+SUM(AC17+AD17)+SUM(AC18+AD18))/3 -> 314.15671 | AE20: =(SUM(AE16+AF16)+SUM(AE17+AF17)+SUM(AE18+AF18))/3 -> 308.13418 | AG20: =(SUM(AG16+AH16)+SUM(AG17+AH17)+SUM(AG18+AH18))/3 -> 312.05242 | AI20: =(SUM(AI16+AJ16)+SUM(AI17+AJ17)+SUM(AI18+AJ18))/3 -> 293.53953 | AK20: =(SUM(AK16+AL16)+SUM(AK17+AL17)+SUM(AK18+AL18))/3 -> 283.11391 | AM20: =(SUM(AM16+AN16)+SUM(AM17+AN17)+SUM(AM18+AN18))/3 -> 265.61808 | AO20: =(SUM(AO16+AP16)+SUM(AO17+AP17)+SUM(AO18+AP18))/3 -> 259.65997 | AQ20: =(SUM(AQ16+AR16)+SUM(AQ17+AR17)+SUM(AQ18+AR18))/3 -> 248.39921 | AS20: =(SUM(AS16+AT16)+SUM(AS17+AT17)+SUM(AS18+AT18))/3 -> 241.41475 | AU20: =(SUM(AU16+AV16)+SUM(AU17+AV17)+SUM(AU18+AV18))/3 -> 221.93308 | AW20: =(SUM(AW16+AX16)+SUM(AW17+AX17)+SUM(AW18+AX18))/3 -> 212.14246

Sheet （日負荷曲線用元データ）
A1: 30分データ | C1: （ｋｗ） | D1: 2019/7/1〜2020/6/30
B2: 0 | C2: 0.020833333 | D2: 0.041666667 | E2: 0.0625 | F2: 0.083333333 | G2: 0.10416667 | H2: 0.125 | I2: 0.14583333 | J2: 0.16666667 | K2: 0.1875 | L2: 0.20833333 | M2: 0.22916667 | N2: 0.25 | O2: 0.27083333 | P2: 0.29166667 | Q2: 0.3125 | R2: 0.33333333 | S2: 0.35416667 | T2: 0.375 | U2: 0.39583333 | V2: 0.41666667 | W2: 0.4375 | X2: 0.45833333 | Y2: 0.47916667 | Z2: 0.5 | AA2: 0.52083333 | AB2: 0.54166667 | AC2: 0.5625 | AD2: 0.58333333 | AE2: 0.60416667 | AF2: 0.625 | AG2: 0.64583333 | AH2: 0.66666667 | AI2: 0.6875 | AJ2: 0.70833333 | AK2: 0.72916667 | AL2: 0.75 | AM2: 0.77083333 | AN2: 0.79166667 | AO2: 0.8125 | AP2: 0.83333333 | AQ2: 0.85416667 | AR2: 0.875 | AS2: 0.89583333 | AT2: 0.91666667 | AU2: 0.9375 | AV2: 0.95833333 | AW2: 0.97916667
A3: 20201101 | B3: 58 | C3: 42 | D3: 41 | E3: 39 | F3: 39 | G3: 42 | H3: 41 | I3: 39 | J3: 37 | K3: 38 | L3: 40 | M3: 51 | N3: 98 | O3: 104 | P3: 105 | Q3: 111 | R3: 115 | S3: 123 | T3: 127 | U3: 132 | V3: 131 | W3: 124 | X3: 127 | Y3: 131 | Z3: 121 | AA3: 132 | AB3: 128 | AC3: 123 | AD3: 119 | AE3: 129 | AF3: 124 | AG3: 121 | AH3: 121 | AI3: 121 | AJ3: 118 | AK3: 113 | AL3: 106 | AM3: 109 | AN3: 108 | AO3: 109 | AP3: 105 | AQ3: 112 | AR3: 113 | AS3: 109 | AT3: 105 | AU3: 104 | AV3: 103 | AW3: 97
A4: 20201102 | B4: 60 | C4: 46 | D4: 46 | E4: 44 | F4: 42 | G4: 48 | H4: 45 | I4: 44 | J4: 41 | K4: 43 | L4: 45 | M4: 54 | N4: 103 | O4: 94 | P4: 105 | Q4: 118 | R4: 112 | S4: 128 | T4: 132 | U4: 128 | V4: 122 | W4: 123 | X4: 120 | Y4: 123 | Z4: 123 | AA4: 123 | AB4: 120 | AC4: 120 | AD4: 112 | AE4: 125 | AF4: 117 | AG4: 121 | AH4: 113 | AI4: 115 | AJ4: 115 | AK4: 116 | AL4: 105 | AM4: 117 | AN4: 107 | AO4: 108 | AP4: 104 | AQ4: 115 | AR4: 111 | AS4: 109 | AT4: 106 | AU4: 105 | AV4: 103 | AW4: 97
A5: 20201103 | B5: 64 | C5: 45 | D5: 47 | E5: 44 | F5: 43 | G5: 48 | H5: 46 | I5: 44 | J5: 43 | K5: 39 | L5: 44 | M5: 54 | N5: 102 | O5: 100 | P5: 114 | Q5: 118 | R5: 115 | S5: 135 | T5: 136 | U5: 125 | V5: 125 | W5: 122 | X5: 127 | Y5: 128 | Z5: 127 | AA5: 134 | AB5: 125 | AC5: 125 | AD5: 118 | AE5: 127 | AF5: 118 | AG5: 116 | AH5: 115 | AI5: 114 | AJ5: 111 | AK5: 111 | AL5: 104 | AM5: 113 | AN5: 114 | AO5: 108 | AP5: 102 | AQ5: 109 | AR5: 108 | AS5: 106 | AT5: 99 | AU5: 99 | AV5: 95 | AW5: 97
A6: 20201104 | B6: 64 | C6: 43 | D6: 43 | E6: 39 | F6: 40 | G6: 44 | H6: 43 | I6: 39 | J6: 38 | K6: 37 | L6: 39 | M6: 50 | N6: 100 | O6: 89 | P6: 100 | Q6: 110 | R6: 109 | S6: 123 | T6: 128 | U6: 114 | V6: 115 | W6: 117 | X6: 120 | Y6: 119 | Z6: 112 | AA6: 114 | AB6: 112 | AC6: 113 | AD6: 111 | AE6: 122 | AF6: 113 | AG6: 107 | AH6: 110 | AI6: 109 | AJ6: 105 | AK6: 109 | AL6: 107 | AM6: 106 | AN6: 101 | AO6: 102 | AP6: 99 | AQ6: 109 | AR6: 104 | AS6: 99 | AT6: 98 | AU6: 93 | AV6: 95 | AW6: 91
A7: 20201105 | B7: 57 | C7: 41 | D7: 42 | E7: 39 | F7: 38 | G7: 41 | H7: 41 | I7: 40 | J7: 36 | K7: 38 | L7: 40 | M7: 51 | N7: 100 | O7: 93 | P7: 104 | Q7: 110 | R7: 115 | S7: 117 | T7: 134 | U7: 123 | V7: 122 | W7: 123 | X7: 123 | Y7: 122 | Z7: 127 | AA7: 124 | AB7: 121 | AC7: 120 | AD7: 117 | AE7: 123 | AF7: 119 | AG7: 118 | AH7: 115 | AI7: 113 | AJ7: 114 | AK7: 113 | AL7: 107 | AM7: 115 | AN7: 112 | AO7: 109 | AP7: 104 | AQ7: 110 | AR7: 110 | AS7: 104 | AT7: 101 | AU7: 99 | AV7: 98 | AW7: 91
A8: 20201106 | B8: 60 | C8: 43 | D8: 42 | E8: 38 | F8: 40 | G8: 42 | H8: 41 | I8: 39 | J8: 37 | K8: 36 | L8: 36 | M8: 41 | N8: 100 | O8: 88 | P8: 100 | Q8: 106 | R8: 112 | S8: 124 | T8: 123 | U8: 123 | V8: 123 | W8: 120 | X8: 124 | Y8: 124 | Z8: 122 | AA8: 122 | AB8: 118 | AC8: 116 | AD8: 114 | AE8: 122 | AF8: 118 | AG8: 116 | AH8: 115 | AI8: 114 | AJ8: 111 | AK8: 111 | AL8: 103 | AM8: 111 | AN8: 106 | AO8: 114 | AP8: 111 | AQ8: 118 | AR8: 113 | AS8: 107 | AT8: 104 | AU8: 103 | AV8: 100 | AW8: 92
A9: 20201107 | B9: 59 | C9: 44 | D9: 45 | E9: 42 | F9: 42 | G9: 45 | H9: 43 | I9: 41 | J9: 40 | K9: 40 | L9: 67 | M9: 63 | N9: 87 | O9: 100 | P9: 108 | Q9: 113 | R9: 114 | S9: 125 | T9: 137 | U9: 128 | V9: 122 | W9: 125 | X9: 118 | Y9: 123 | Z9: 124 | AA9: 126 | AB9: 120 | AC9: 119 | AD9: 119 | AE9: 122 | AF9: 120 | AG9: 121 | AH9: 123 | AI9: 116 | AJ9: 113 | AK9: 110 | AL9: 104 | AM9: 111 | AN9: 107 | AO9: 111 | AP9: 112 | AQ9: 118 | AR9: 115 | AS9: 110 | AT9: 103 | AU9: 104 | AV9: 101 | AW9: 102
A10: 20201108 | B10: 73 | C10: 57 | D10: 57 | E10: 54 | F10: 54 | G10: 59 | H10: 58 | I10: 47 | J10: 43 | K10: 43 | L10: 45 | M10: 61 | N10: 107 | O10: 95 | P10: 110 | Q10: 115 | R10: 122 | S10: 129 | T10: 138 | U10: 133 | V10: 130 | W10: 125 | X10: 132 | Y10: 130 | Z10: 126 | AA10: 133 | AB10: 129 | AC10: 125 | AD10: 119 | AE10: 132 | AF10: 124 | AG10: 124 | AH10: 122 | AI10: 124 | AJ10: 120 | AK10: 115 | AL10: 107 | AM10: 115 | AN10: 106 | AO10: 111 | AP10: 106 | AQ10: 114 | AR10: 110 | AS10: 107 | AT10: 101 | AU10: 102 | AV10: 98 | AW10: 98
A11: 20201109 | B11: 60 | C11: 43 | D11: 42 | E11: 39 | F11: 39 | G11: 44 | H11: 42 | I11: 39 | J11: 37 | K11: 37 | L11: 39 | M11: 51 | N11: 89 | O11: 75 | P11: 87 | Q11: 97 | R11: 99 | S11: 114 | T11: 116 | U11: 119 | V11: 111 | W11: 112 | X11: 114 | Y11: 110 | Z11: 112 | AA11: 116 | AB11: 109 | AC11: 106 | AD11: 101 | AE11: 111 | AF11: 105 | AG11: 110 | AH11: 103 | AI11: 101 | AJ11: 100 | AK11: 96 | AL11: 99 | AM11: 106 | AN11: 103 | AO11: 100 | AP11: 95 | AQ11: 100 | AR11: 98 | AS11: 92 | AT11: 91 | AU11: 87 | AV11: 88 | AW11: 80
A12: 20201110 | B12: 53 | C12: 40 | D12: 39 | E12: 36 | F12: 37 | G12: 41 | H12: 39 | I12: 38 | J12: 34 | K12: 36 | L12: 37 | M12: 48 | N12: 90 | O12: 91 | P12: 102 | Q12: 102 | R12: 106 | S12: 121 | T12: 122 | U12: 121 | V12: 125 | W12: 115 | X12: 123 | Y12: 117 | Z12: 120 | AA12: 129 | AB12: 117 | AC12: 118 | AD12: 120 | AE12: 119 | AF12: 117 | AG12: 114 | AH12: 112 | AI12: 111 | AJ12: 110 | AK12: 108 | AL12: 108 | AM12: 112 | AN12: 114 | AO12: 107 | AP12: 103 | AQ12: 106 | AR12: 103 | AS12: 100 | AT12: 97 | AU12: 95 | AV12: 94 | AW12: 94
A13: 20201111 | B13: 58 | C13: 41 | D13: 40 | E13: 36 | F13: 37 | G13: 40 | H13: 40 | I13: 38 | J13: 35 | K13: 37 | L13: 37 | M13: 50 | N13: 93 | O13: 88 | P13: 106 | Q13: 110 | R13: 109 | S13: 122 | T13: 119 | U13: 121 | V13: 115 | W13: 114 | X13: 116 | Y13: 118 | Z13: 117 | AA13: 115 | AB13: 113 | AC13: 112 | AD13: 108 | AE13: 121 | AF13: 112 | AG13: 110 | AH13: 108 | AI13: 106 | AJ13: 109 | AK13: 100 | AL13: 95 | AM13: 101 | AN13: 101 | AO13: 104 | AP13: 100 | AQ13: 113 | AR13: 101 | AS13: 97 | AT13: 93 | AU13: 93 | AV13: 91 | AW13: 90
A14: 20201112 | B14: 60 | C14: 40 | D14: 39 | E14: 34 | F14: 36 | G14: 39 | H14: 38 | I14: 35 | J14: 35 | K14: 34 | L14: 36 | M14: 49 | N14: 103 | O14: 87 | P14: 101 | Q14: 111 | R14: 115 | S14: 120 | T14: 129 | U14: 125 | V14: 119 | W14: 123 | X14: 123 | Y14: 123 | Z14: 123 | AA14: 129 | AB14: 124 | AC14: 128 | AD14: 116 | AE14: 128 | AF14: 123 | AG14: 117 | AH14: 117 | AI14: 114 | AJ14: 112 | AK14: 109 | AL14: 102 | AM14: 109 | AN14: 107 | AO14: 109 | AP14: 109 | AQ14: 112 | AR14: 111 | AS14: 103 | AT14: 99 | AU14: 96 | AV14: 97 | AW14: 84
... A20: 20201118 | B20: 56 | C20: 42 | D20: 40 | E20: 37 | F20: 38 | G20: 41 | H20: 41 | I20: 40 | J20: 36 | K20: 37 | L20: 39 | M20: 50 | N20: 101 | O20: 99 | P20: 101 | Q20: 115 | R20: 114 | S20: 127 | T20: 131 | U20: 132 | V20: 128 | W20: 126 | X20: 131 | Y20: 128 | Z20: 128 | AA20: 140 | AB20: 136 | AC20: 132 | AD20: 128 | AE20: 138 | AF20: 135 | AG20: 129 | AH20: 119 | AI20: 119 | AJ20: 120 | AK20: 117 | AL20: 106 | AM20: 112 | AN20: 110 | AO20: 107 | AP20: 105 | AQ20: 111 | AR20: 112 | AS20: 111 | AT20: 105 | AU20: 103 | AV20: 101 | AW20: 104
A21: 20201119 | B21: 71 | C21: 50 | D21: 50 | E21: 46 | F21: 45 | G21: 49 | H21: 49 | I21: 48 | J21: 45 | K21: 44 | L21: 47 | M21: 56 | N21: 107 | O21: 99 | P21: 113 | Q21: 117 | R21: 117 | S21: 133 | T21: 140 | U21: 129 | V21: 128 | W21: 130 | X21: 133 | Y21: 137 | Z21: 133 | AA21: 139 | AB21: 132 | AC21: 136 | AD21: 126 | AE21: 146 | AF21: 138 | AG21: 136 | AH21: 129 | AI21: 130 | AJ21: 128 | AK21: 122 | AL21: 113 | AM21: 126 | AN21: 123 | AO21: 120 | AP21: 119 | AQ21: 123 | AR21: 119 | AS21: 119 | AT21: 111 | AU21: 105 | AV21: 94 | AW21: 94 | AX21: 22.344 | AY21: 22.908
A22: 20201120 | B22: 64 | C22: 49 | D22: 49 | E22: 47 | F22: 46 | G22: 51 | H22: 50 | I22: 49 | J22: 45 | K22: 44 | L22: 47 | M22: 57 | N22: 110 | O22: 107 | P22: 109 | Q22: 114 | R22: 121 | S22: 136 | T22: 140 | U22: 130 | V22: 127 | W22: 132 | X22: 138 | Y22: 139 | Z22: 122 | AA22: 131 | AB22: 129 | AC22: 122 | AD22: 111 | AE22: 129 | AF22: 119 | AG22: 123 | AH22: 120 | AI22: 118 | AJ22: 117 | AK22: 117 | AL22: 113 | AM22: 122 | AN22: 113 | AO22: 115 | AP22: 107 | AQ22: 116 | AR22: 112 | AS22: 111 | AT22: 106 | AU22: 103 | AV22: 103 | AW22: 91
A23: 20201121 | B23: 66 | C23: 47 | D23: 47 | E23: 44 | F23: 41 | G23: 48 | H23: 46 | I23: 46 | J23: 41 | K23: 43 | L23: 44 | M23: 65 | N23: 99 | O23: 91 | P23: 111 | Q23: 116 | R23: 113 | S23: 131 | T23: 134 | U23: 130 | V23: 121 | W23: 121 | X23: 124 | Y23: 123 | Z23: 125 | AA23: 126 | AB23: 124 | AC23: 118 | AD23: 113 | AE23: 122 | AF23: 118 | AG23: 118 | AH23: 114 | AI23: 114 | AJ23: 108 | AK23: 107 | AL23: 101 | AM23: 110 | AN23: 110 | AO23: 107 | AP23: 101 | AQ23: 111 | AR23: 106 | AS23: 105 | AT23: 102 | AU23: 100 | AV23: 100 | AW23: 93
A24: 20201122 | B24: 56 | C24: 42 | D24: 41 | E24: 38 | F24: 38 | G24: 42 | H24: 42 | I24: 40 | J24: 37 | K24: 36 | L24: 37 | M24: 52 | N24: 106 | O24: 91 | P24: 108 | Q24: 117 | R24: 111 | S24: 129 | T24: 134 | U24: 131 | V24: 131 | W24: 126 | X24: 125 | Y24: 129 | Z24: 128 | AA24: 128 | AB24: 122 | AC24: 128 | AD24: 118 | AE24: 129 | AF24: 122 | AG24: 124 | AH24: 121 | AI24: 118 | AJ24: 114 | AK24: 117 | AL24: 111 | AM24: 117 | AN24: 117 | AO24: 114 | AP24: 110 | AQ24: 118 | AR24: 113 | AS24: 110 | AT24: 107 | AU24: 105 | AV24: 104 | AW24: 100
A25: 20201123 | B25: 66 | C25: 47 | D25: 47 | E25: 45 | F25: 43 | G25: 47 | H25: 45 | I25: 44 | J25: 41 | K25: 40 | L25: 40 | M25: 54 | N25: 104 | O25: 98 | P25: 109 | Q25: 116 | R25: 110 | S25: 130 | T25: 129 | U25: 127 | V25: 126 | W25: 123 | X25: 123 | Y25: 118 | Z25: 124 | AA25: 123 | AB25: 113 | AC25: 116 | AD25: 114 | AE25: 120 | AF25: 120 | AG25: 116 | AH25: 114 | AI25: 118 | AJ25: 113 | AK25: 114 | AL25: 111 | AM25: 112 | AN25: 110 | AO25: 111 | AP25: 105 | AQ25: 110 | AR25: 108 | AS25: 101 | AT25: 99 | AU25: 98 | AV25: 99 | AW25: 84
A26: 20201124 | B26: 58 | C26: 42 | D26: 41 | E26: 37 | F26: 38 | G26: 43 | H26: 40 | I26: 39 | J26: 37 | K26: 35 | L26: 35 | M26: 50 | N26: 87 | O26: 91 | P26: 92 | Q26: 108 | R26: 110 | S26: 122 | T26: 130 | U26: 128 | V26: 122 | W26: 121 | X26: 122 | Y26: 120 | Z26: 119 | AA26: 123 | AB26: 126 | AC26: 125 | AD26: 116 | AE26: 122 | AF26: 121 | AG26: 115 | AH26: 116 | AI26: 113 | AJ26: 112 | AK26: 110 | AL26: 105 | AM26: 113 | AN26: 109 | AO26: 113 | AP26: 102 | AQ26: 112 | AR26: 104 | AS26: 100 | AT26: 100 | AU26: 95 | AV26: 96 | AW26: 92
A27: 20201125 | B27: 60 | C27: 42 | D27: 40 | E27: 37 | F27: 37 | G27: 41 | H27: 40 | I27: 39 | J27: 36 | K27: 36 | L27: 41 | M27: 50 | N27: 96 | O27: 94 | P27: 103 | Q27: 116 | R27: 114 | S27: 121 | T27: 127 | U27: 120 | V27: 121 | W27: 123 | X27: 125 | Y27: 119 | Z27: 117 | AA27: 125 | AB27: 117 | AC27: 119 | AD27: 110 | AE27: 125 | AF27: 118 | AG27: 117 | AH27: 112 | AI27: 114 | AJ27: 111 | AK27: 109 | AL27: 106 | AM27: 112 | AN27: 108 | AO27: 113 | AP27: 107 | AQ27: 110 | AR27: 110 | AS27: 103 | AT27: 103 | AU27: 99 | AV27: 98 | AW27: 93
A28: 20201126 | B28: 56 | C28: 41 | D28: 43 | E28: 38 | F28: 38 | G28: 42 | H28: 43 | I28: 40 | J28: 39 | K28: 38 | L28: 41 | M28: 50 | N28: 105 | O28: 91 | P28: 107 | Q28: 111 | R28: 116 | S28: 129 | T28: 132 | U28: 129 | V28: 123 | W28: 127 | X28: 125 | Y28: 124 | Z28: 118 | AA28: 129 | AB28: 122 | AC28: 124 | AD28: 117 | AE28: 125 | AF28: 114 | AG28: 118 | AH28: 117 | AI28: 116 | AJ28: 109 | AK28: 110 | AL28: 105 | AM28: 109 | AN28: 106 | AO28: 109 | AP28: 108 | AQ28: 119 | AR28: 108 | AS28: 109 | AT28: 105 | AU28: 98 | AV28: 96 | AW28: 92
A29: 20201127 | B29: 60 | C29: 42 | D29: 41 | E29: 37 | F29: 38 | G29: 42 | H29: 40 | I29: 40 | J29: 37 | K29: 37 | L29: 37 | M29: 51 | N29: 90 | O29: 100 | P29: 99 | Q29: 109 | R29: 109 | S29: 121 | T29: 124 | U29: 127 | V29: 122 | W29: 118 | X29: 122 | Y29: 116 | Z29: 115 | AA29: 123 | AB29: 122 | AC29: 117 | AD29: 111 | AE29: 119 | AF29: 116 | AG29: 116 | AH29: 112 | AI29: 112 | AJ29: 109 | AK29: 110 | AL29: 108 | AM29: 114 | AN29: 110 | AO29: 106 | AP29: 106 | AQ29: 109 | AR29: 109 | AS29: 105 | AT29: 101 | AU29: 101 | AV29: 97 | AW29: 97
A30: 20201128 | B30: 64 | C30: 42 | D30: 41 | E30: 38 | F30: 38 | G30: 43 | H30: 46 | I30: 44 | J30: 43 | K30: 43 | L30: 42 | M30: 54 | N30: 87 | O30: 78 | P30: 92 | Q30: 98 | R30: 112 | S30: 123 | T30: 132 | U30: 128 | V30: 124 | W30: 122 | X30: 122 | Y30: 120 | Z30: 122 | AA30: 123 | AB30: 119 | AC30: 115 | AD30: 112 | AE30: 125 | AF30: 119 | AG30: 119 | AH30: 116 | AI30: 114 | AJ30: 106 | AK30: 110 | AL30: 107 | AM30: 110 | AN30: 111 | AO30: 113 | AP30: 112 | AQ30: 111 | AR30: 104 | AS30: 101 | AT30: 97 | AU30: 99 | AV30: 94 | AW30: 94
A31: 20201129 | B31: 57 | C31: 41 | D31: 39 | E31: 36 | F31: 37 | G31: 40 | H31: 43 | I31: 42 | J31: 41 | K31: 41 | L31: 40 | M31: 43 | N31: 92 | O31: 79 | P31: 90 | Q31: 104 | R31: 113 | S31: 122 | T31: 131 | U31: 123 | V31: 125 | W31: 125 | X31: 117 | Y31: 122 | Z31: 121 | AA31: 128 | AB31: 126 | AC31: 126 | AD31: 115 | AE31: 122 | AF31: 120 | AG31: 120 | AH31: 118 | AI31: 113 | AJ31: 112 | AK31: 112 | AL31: 107 | AM31: 117 | AN31: 112 | AO31: 110 | AP31: 107 | AQ31: 110 | AR31: 107 | AS31: 103 | AT31: 97 | AU31: 99 | AV31: 94 | AW31: 89
A32: 20201130 | B32: 54 | C32: 40 | D32: 40 | E32: 36 | F32: 37 | G32: 40 | H32: 39 | I32: 38 | J32: 35 | K32: 35 | L32: 36 | M32: 50 | N32: 92 | O32: 80 | P32: 97 | Q32: 102 | R32: 121 | S32: 122 | T32: 124 | U32: 122 | V32: 120 | W32: 118 | X32: 119 | Y32: 117 | Z32: 119 | AA32: 124 | AB32: 117 | AC32: 115 | AD32: 116 | AE32: 119 | AF32: 114 | AG32: 116 | AH32: 114 | AI32: 111 | AJ32: 108 | AK32: 102 | AL32: 102 | AM32: 106 | AN32: 106 | AO32: 107 | AP32: 99 | AQ32: 105 | AR32: 103 | AS32: 99 | AT32: 97 | AU32: 96 | AV32: 97 | AW32: 90
B33: =AVERAGE(B3:B3) -> 58 | C33: =AVERAGE(C3:C3) -> 42 | D33: =AVERAGE(D3:D3) -> 41 | E33: =AVERAGE(E3:E3) -> 39 | F33: =AVERAGE(F3:F3) -> 39 | G33: =AVERAGE(G3:G3) -> 42 | H33: =AVERAGE(H3:H3) -> 41 | I33: =AVERAGE(I3:I3) -> 39 | ... AC33: =AVERAGE(AC3:AC3) -> 123 | AD33: =AVERAGE(AD3:AD31) -> 115.51724 | AE33: =AVERAGE(AE3:AE31) -> 125.48276 | AF33: =AVERAGE(AF3:AF31) -> 120.44828 | AG33: =AVERAGE(AG3:AG31) -> 118.93103 | AH33: =AVERAGE(AH3:AH31) -> 116.03448 | AI33: =AVERAGE(AI3:AI31) -> 115.27586 | AJ33: =AVERAGE(AJ3:AJ31) -> 112.68966 | AK33: =AVERAGE(AK3:AK31) -> 111.41379 | ... AW33: =AVERAGE(AW3:AW31) -> 92.068966
B34: =AVERAGE(B3:C33) -> 51.612903 | D34: =AVERAGE(D3:E33) -> 41.290323 | F34: =AVERAGE(F3:G33) -> 41.741935 | H34: =AVERAGE(H3:I33) -> 41.822581 | J34: =AVERAGE(J3:K33) -> 38.241935 | L34: =AVERAGE(L3:M33) -> 46.177419 | N34: =AVERAGE(N3:O33) -> 95.419355 | P34: =AVERAGE(P3:Q33) -> 107.41935 | R34: =AVERAGE(R3:S33) -> 119.09677 | T34: =AVERAGE(T3:U33) -> 128.12903 | V34: =AVERAGE(V3:W33) -> 122.87097 | X34: =AVERAGE(X3:Y33) -> 123.80645 | Z34: =AVERAGE(Z3:AA33) -> 124.48387 | AB34: =AVERAGE(AB3:AC33) -> 121.70968 | AD34: =AVERAGE(AD3:AE33) -> 120.40323 | AF34: =AVERAGE(AF3:AG33) -> 119.53838 | AH34: =AVERAGE(AH3:AI33) -> 115.55339 | AJ34: =AVERAGE(AJ3:AK33) -> 111.82425 | AL34: =AVERAGE(AL3:AM33) -> 109.45606 | AN34: =AVERAGE(AN3:AO33) -> 109.41991 | AP34: =AVERAGE(AP3:AQ33) -> 109.07453 | AR34: =AVERAGE(AR3:AS33) -> 106.80645 | AT34: =AVERAGE(AT3:AU33) -> 100.2208 | AV34: =AVERAGE(AV3:AW33) -> 94.617909
A35: 20201201 | B35: 56 | C35: 40 | D35: 40 | E35: 36 | F35: 37 | G35: 41 | H35: 40 | I35: 37 | J35: 35 | K35: 36 | L35: 35 | M35: 39 | N35: 88 | O35: 78 | P35: 93 | Q35: 100 | R35: 106 | S35: 121 | T35: 128 | U35: 122 | V35: 120 | W35: 119 | X35: 126 | Y35: 115 | Z35: 114 | AA35: 115 | AB35: 109 | AC35: 114 | AD35: 107 | AE35: 118 | AF35: 120 | AG35: 120 | AH35: 114 | AI35: 107 | AJ35: 107 | AK35: 107 | AL35: 104 | AM35: 108 | AN35: 107 | AO35: 108 | AP35: 102 | AQ35: 105 | AR35: 102 | AS35: 98 | AT35: 94 | AU35: 96 | AV35: 92 | AW35: 93
A36: 20201202 | B36: 58 | C36: 41 | D36: 39 | E36: 35 | F36: 36 | G36: 40 | H36: 38 | I36: 37 | J36: 35 | K36: 34 | L36: 35 | M36: 49 | N36: 97 | O36: 93 | P36: 105 | Q36: 110 | R36: 112 | S36: 123 | T36: 126 | U36: 123 | V36: 121 | W36: 117 | X36: 120 | Y36: 123 | Z36: 123 | AA36: 127 | AB36: 120 | AC36: 119 | AD36: 117 | AE36: 128 | AF36: 124 | AG36: 113 | AH36: 116 | AI36: 109 | AJ36: 110 | AK36: 103 | AL36: 106 | AM36: 110 | AN36: 106 | AO36: 106 | AP36: 101 | AQ36: 107 | AR36: 106 | AS36: 101 | AT36: 97 | AU36: 98 | AV36: 95 | AW36: 79
A37: 20201203 | B37: 58 | C37: 41 | D37: 39 | E37: 36 | F37: 37 | G37: 41 | H37: 41 | I37: 38 | J37: 36 | K37: 35 | L37: 39 | M37: 48 | N37: 97 | O37: 93 | P37: 107 | Q37: 116 | R37: 115 | S37: 119 | T37: 127 | U37: 126 | V37: 122 | W37: 119 | X37: 124 | Y37: 120 | Z37: 123 | AA37: 127 | AB37: 117 | AC37: 117 | AD37: 121 | AE37: 127 | AF37: 116 | AG37: 119 | AH37: 116 | AI37: 114 | AJ37: 115 | AK37: 112 | AL37: 108 | AM37: 113 | AN37: 113 | AO37: 120 | AP37: 106 | AQ37: 108 | AR37: 104 | AS37: 100 | AT37: 97 | AU37: 98 | AV37: 95 | AW37: 88
A38: 20201204 | B38: 55 | C38: 40 | D38: 40 | E38: 35 | F38: 37 | G38: 40 | H38: 39 | I38: 35 | J38: 35 | K38: 36 | L38: 37 | M38: 48 | N38: 87 | O38: 78 | P38: 91 | Q38: 102 | R38: 97 | S38: 120 | T38: 115 | U38: 115 | V38: 114 | W38: 114 | X38: 116 | Y38: 123 | Z38: 119 | AA38: 119 | AB38: 116 | AC38: 116 | AD38: 116 | AE38: 121 | AF38: 120 | AG38: 117 | AH38: 113 | AI38: 106 | AJ38: 106 | AK38: 103 | AL38: 101 | AM38: 106 | AN38: 103 | AO38: 101 | AP38: 100 | AQ38: 99 | AR38: 97 | AS38: 93 | AT38: 88 | AU38: 89 | AV38: 87 | AW38: 87
A39: 20201205 | B39: 57 | C39: 39 | D39: 36 | E39: 34 | F39: 34 | G39: 37 | H39: 37 | I39: 34 | J39: 33 | K39: 33 | L39: 38 | M39: 46 | N39: 85 | O39: 89 | P39: 91 | Q39: 101 | R39: 113 | S39: 123 | T39: 127 | U39: 129 | V39: 120 | W39: 123 | X39: 124 | Y39: 123 | Z39: 118 | AA39: 126 | AB39: 123 | AC39: 119 | AD39: 113 | AE39: 126 | AF39: 121 | AG39: 124 | AH39: 120 | AI39: 115 | AJ39: 112 | AK39: 112 | AL39: 109 | AM39: 113 | AN39: 107 | AO39: 113 | AP39: 117 | AQ39: 116 | AR39: 112 | AS39: 103 | AT39: 97 | AU39: 98 | AV39: 96 | AW39: 92
A40: 20201206 | B40: 54 | C40: 41 | D40: 38 | E40: 34 | F40: 36 | G40: 39 | H40: 39 | I40: 36 | J40: 34 | K40: 35 | L40: 38 | M40: 49 | N40: 102 | O40: 98 | P40: 110 | Q40: 112 | R40: 112 | S40: 120 | T40: 128 | U40: 128 | V40: 119 | W40: 124 | X40: 127 | Y40: 130 | Z40: 125 | AA40: 127 | AB40: 126 | AC40: 123 | AD40: 123 | AE40: 130 | AF40: 129 | AG40: 123 | AH40: 121 | AI40: 119 | AJ40: 117 | AK40: 116 | AL40: 111 | AM40: 117 | AN40: 111 | AO40: 111 | AP40: 108 | AQ40: 112 | AR40: 107 | AS40: 102 | AT40: 99 | AU40: 98 | AV40: 96 | AW40: 97
A41: 20201207 | B41: 58 | C41: 41 | D41: 39 | E41: 34 | F41: 37 | G41: 38 | H41: 39 | I41: 37 | J41: 34 | K41: 35 | L41: 38 | M41: 50 | N41: 104 | O41: 94 | P41: 106 | Q41: 114 | R41: 112 | S41: 131 | T41: 126 | U41: 126 | V41: 119 | W41: 124 | X41: 125 | Y41: 120 | Z41: 124 | AA41: 127 | AB41: 125 | AC41: 120 | AD41: 117 | AE41: 129 | AF41: 121 | AG41: 124 | AH41: 115 | AI41: 112 | AJ41: 111 | AK41: 108 | AL41: 106 | AM41: 116 | AN41: 107 | AO41: 108 | AP41: 100 | AQ41: 109 | AR41: 107 | AS41: 105 | AT41: 99 | AU41: 99 | AV41: 101 | AW41: 90
A42: 20201208 | B42: 57 | C42: 42 | D42: 41 | E42: 37 | F42: 37 | G42: 42 | H42: 41 | I42: 39 | J42: 35 | K42: 37 | L42: 40 | M42: 51 | N42: 105 | O42: 94 | P42: 104 | Q42: 110 | R42: 114 | S42: 122 | T42: 126 | U42: 120 | V42: 121 | W42: 119 | X42: 119 | Y42: 123 | Z42: 114 | AA42: 125 | AB42: 120 | AC42: 117 | AD42: 114 | AE42: 116 | AF42: 117 | AG42: 113 | AH42: 112 | AI42: 109 | AJ42: 111 | AK42: 108 | AL42: 108 | AM42: 111 | AN42: 109 | AO42: 107 | AP42: 105 | AQ42: 106 | AR42: 104 | AS42: 98 | AT42: 97 | AU42: 95 | AV42: 95 | AW42: 86
A43: 20201209 | B43: 58 | C43: 41 | D43: 39 | E43: 35 | F43: 36 | G43: 39 | H43: 39 | I43: 37 | J43: 33 | K43: 35 | L43: 34 | M43: 38 | N43: 96 | O43: 100 | P43: 100 | Q43: 112 | R43: 110 | S43: 122 | T43: 126 | U43: 121 | V43: 120 | W43: 117 | X43: 117 | Y43: 116 | Z43: 122 | AA43: 121 | AB43: 112 | AC43: 121 | AD43: 117 | AE43: 123 | AF43: 116 | AG43: 118 | AH43: 115 | AI43: 115 | AJ43: 109 | AK43: 110 | AL43: 107 | AM43: 112 | AN43: 107 | AO43: 104 | AP43: 98 | AQ43: 103 | AR43: 100 | AS43: 95 | AT43: 89 | AU43: 91 | AV43: 90 | AW43: 75
A44: 20201210 | B44: 58 | C44: 40 | D44: 37 | E44: 34 | F44: 34 | G44: 36 | H44: 36 | I44: 33 | J44: 33 | K44: 31 | L44: 34 | M44: 47 | N44: 100 | O44: 89 | P44: 105 | Q44: 110 | R44: 110 | S44: 122 | T44: 122 | U44: 120 | V44: 121 | W44: 120 | X44: 126 | Y44: 123 | Z44: 125 | AA44: 123 | AB44: 114 | AC44: 126 | AD44: 114 | AE44: 126 | AF44: 120 | AG44: 117 | AH44: 113 | AI44: 113 | AJ44: 109 | AK44: 109 | AL44: 101 | AM44: 116 | AN44: 115 | AO44: 110 | AP44: 108 | AQ44: 117 | AR44: 108 | AS44: 105 | AT44: 99 | AU44: 95 | AV44: 99 | AW44: 88
A45: 20201211 | B45: 54 | C45: 42 | D45: 41 | E45: 35 | F45: 37 | G45: 40 | H45: 39 | I45: 37 | J45: 36 | K45: 35 | L45: 38 | M45: 62 | N45: 100 | O45: 97 | P45: 108 | Q45: 113 | R45: 109 | S45: 121 | T45: 133 | U45: 122 | V45: 120 | W45: 116 | X45: 124 | Y45: 124 | Z45: 124 | AA45: 127 | AB45: 126 | AC45: 119 | AD45: 118 | AE45: 126 | AF45: 119 | AG45: 120 | AH45: 113 | AI45: 113 | AJ45: 111 | AK45: 112 | AL45: 110 | AM45: 119 | AN45: 109 | AO45: 113 | AP45: 103 | AQ45: 112 | AR45: 108 | AS45: 105 | AT45: 100 | AU45: 99 | AV45: 99 | AW45: 99
...

Sheet （日負荷用基本データ）
A1: 日射データ地点
A2: 太陽電池モジュール設置方位 | D2: 0度南
A3: 太陽電池設置角度 | D3: 0度
A4: システム容量 | D4: =9.9*22 -> 217.8 | E4: （ＫＷ） | G4: 10 | H4: 9.9
A5: モジュール容量 | D5: =0.38*880 -> 334.4 | E5: （ＫＷ） | G5: 379 | H5: 0.315
B7: 1月 | C7: 2月 | D7: 3月 | E7: 4月 | F7: 5月 | G7: 6月 | H7: 7月 | I7: 8月 | J7: 9月 | K7: 10月 | L7: 11月 | M7: 12月 | N7: 年間合計
A8: 日射量 | B8: 1.31 | C8: 1.87 | D8: 2.85 | E8: 4 | F8: 5.27 | G8: 5.35 | H8: 4.73 | I8: 4.83 | J8: 3.97 | K8: 2.79 | L8: 1.69 | M8: 1.13 | N8: =SUM(B8:M8) -> 39.79
A9: 発電量 | B9: 12228 | C9: 15579 | D9: 25619 | E9: 33182 | F9: 43902 | G9: 42868 | H9: 39248 | I9: 40571 | J9: 33064 | K9: 24989 | L9: 15036 | M9: 10450 | N9: =SUM(B9:M9) -> 336736 | O9: =AVERAGE(B9:M9) -> 28061.333
B10: 冬 | C10: 冬 | D10: 冬 | E10: 春 | F10: 春 | G10: 夏 | H10: 夏 | I10: 夏 | J10: 秋 | K10: 秋 | L10: 冬 | M10: 冬
A12: 容量 | B12: 12.375 | C12: =B12 -> 12.375 | D12: =B12 -> 12.375
A13: INVロス | B13: 0.95 | C13: 0.95 | D13: 0.95
A14: その他ロス | B14: 0.95 | C14: 0.95 | D14: 0.95 | F14: 9月秋分 | H14: 6月夏至 | J14: 12月冬至
B15: 春秋 | C15: 夏 | D15: 冬 | F15: 春秋 | H15: 夏 | J15: 冬
A16: 時刻 | B16: 日射量MJ | C16: 日射量MJ | D16: 日射量MJ | E16: 時刻 | F16: 発電 （ＫＷ） | H16: 発電 （ＫＷ） | J16: 発電 （ＫＷ）
A18: 1 | B18: 0 | C18: 0 | D18: 0 | E18: 1 | F18: =$F$42*G18 -> 0 | G18: 0 | H18: =$H$42*I18 -> 0 | I18: 0 | J18: =$J$42*K18 -> 0 | K18: 0
A19: 2 | B19: 0 | C19: 0 | D19: 0 | E19: 2 | F19: =$F$42*G19 -> 0 | G19: 0 | H19: =$H$42*I19 -> 0 | I19: 0 | J19: =$J$42*K19 -> 0 | K19: 0
A20: 3 | B20: 0 | C20: 0 | D20: 0 | E20: 3 | F20: =$F$42*G20 -> 0 | G20: 0 | H20: =$H$42*I20 -> 0 | I20: 0 | J20: =$J$42*K20 -> 0 | K20: 0
A21: 4 | B21: 0 | C21: 0 | D21: 0 | E21: 4 | F21: =$F$42*G21 -> 0 | G21: 0 | H21: =$H$42*I21 -> 0 | I21: 0 | J21: =$J$42*K21 -> 0 | K21: 0
A22: 5 | B22: 0 | C22: 0.02 | D22: 0 | E22: 5 | F22: =$F$42*G22 -> 0 | G22: 0 | H22: =$H$42*I22 -> 0.026218977 | I22: 1.9233561e-05 | J22: =$J$42*K22 -> 0 | K22: 0
A23: 6 | B23: 0.11 | C23: 0.26 | D23: 0 | E23: 6 | F23: =$F$42*G23 -> 0.023514223 | G23: 1.6061801e-05 | H23: =$H$42*I23 -> 0.13259311 | I23: 9.7266866e-05 | J23: =$J$42*K23 -> 0 | K23: 0
A24: 7 | B24: 0.69 | C24: 0.92 | D24: 0 | E24: 7 | F24: =$F$42*G24 -> 0.040310096 | G24: 2.7534516e-05 | H24: =$H$42*I24 -> 0.28990697 | I24: 0.00021266823 | J24: =$J$42*K24 -> 0.0050061236 | K24: 5.4825579e-06
A25: 8 | B25: 1.43 | C25: 1.65 | D25: 0.09 | E25: 8 | F25: =$F$42*G25 -> 0.09674423 | G25: 6.6082839e-05 | H25: =$H$42*I25 -> 44.946817 | I25: 0.032971819 | J25: =$J$42*K25 -> 0.080097977 | K25: 8.7720926e-05
A26: 9 | B26: 2.19 | C26: 2.3 | D26: 0.78 | E26: 9 | F26: =$F$42*G26 -> 32.248077 | G26: 0.022027613 | H26: =$H$42*I26 -> 58.430862 | I26: 0.042863365 | J26: =$J$42*K26 -> 39.548376 | K26: 0.043312207
A27: 10 | B27: 2.81 | C27: 2.88 | D27: 1.39 | E27: 10 | F27: =$F$42*G27 -> 77.12665 | G27: 0.052682708 | H27: =$H$42*I27 -> 82.327587 | I27: 0.060393382 | J27: =$J$42*K27 -> 95.005101 | K27: 0.10404676
A28: 11 | B28: 3.21 | C28: 3.23 | D28: 1.76 | E28: 11 | F28: =$F$42*G28 -> 257.98461 | G28: 0.1762209 | H28: =$H$42*I28 -> 104.27662 | I28: 0.07649462 | J28: =$J$42*K28 -> 166.87079 | K28: 0.18275193
A29: 12 | B29: 3.45 | C29: 3.48 | D29: 2.02 | E29: 12 | F29: =$F$42*G29 -> 268.73397 | G29: 0.18356344 | H29: =$H$42*I29 -> 268.93179 | I29: 0.19728138 | J29: =$J$42*K29 -> 177.16115 | K29: 0.19402163
... A41: 24 | B41: 0 | C41: 0 | D41: 0 | E41: 24 | F41: =$F$42*G41 -> 0 | G41: 0 | H41: =$H$42*I41 -> 0 | I41: 0 | J41: =$J$42*K41 -> 0 | K41: 0
A42: 合計 | B42: =SUM(B18:B41) -> 26.9 | C42: =SUM(C18:C41) -> 28.31 | D42: =SUM(D18:D41) -> 11.41 | E42: 合計 | F42: =((E9+F9+J9+K9)/4)/30*1.3 -> 1463.9842 | H42: =((G9+H9+I9)/3)/30 -> 1363.1889 | J42: =((J9+K9+L9+M9+B9+C9+D9)/7)/30*1.4 -> 913.1
A43: 最大 | B43: =MAX(B18:B41) -> 3.45 | C43: =MAX(C18:C41) -> 3.48 | D43: =MAX(D18:D41) -> 2.02 | E43: 最大 | F43: =MAX(F18:F41) -> 268.73397 | H43: =MAX(H18:H41) -> 268.93179 | J43: =MAX(J18:J41) -> 177.16115
A45: ＮＥＤＯの日射積算ランキング（晴天日を想定した）データーを使用。

Sheet 様式３（回転機）
L1: 様式３
K3: 年 月 日
A4: 主要設備仕様（回転機）
H5: 発電設備等設置者名
I6: 号発電機 | J6: （既設 ・ 新設 ・ 増設）
A7: １．一般
B8: （１）原動機の種類（内燃機関、風力など）
B9: （２）発電機の種類（同期発電機、誘導発電機）
B10: （３）発電機台数 | H10: 台
B11: （４）運転可能周波数 | H11: Hz ～ Hz
H12: Hz
B13: （５）自動電圧調整装置（AVR）の有無 | H13: 有 ・ 無
B14: （６）自動電圧調整装置（AVR）の定数（整定値）
A16: ２．昇圧用変圧器
B17: （１）定格容量 | H17: kVA
B18: （２）定格１次電圧／２次電圧 | H18: V ／ kV
B19: （３）タップ切替器仕様 | F19: タップ数
F20: 電圧調整範囲
B21: （４）％インピーダンス（変圧器定格容量ベース）
A23: ３．交流発電機
B24: 共通事項 | C24: 容 量 | D24: kVA
C25: 定格電圧 | D25: V
C26: 定格出力 | D26: kW
C27: 出力抑制時の最低出力 （火力・バイオマスの場合） | D27: kW
C28: 力率（定格） | D28: % | G28: 力率（運転可能範囲）
C29: ＦＲＴ要件適用の有無 | D29: 有 ・ 無
B30: 同期発電機 | D30: （a）Xd（同期リアクタンス） | K30: %
D31: （b）Xd'（過渡リアクタンス） | K31: %
D32: （c）Xd''（初期過渡リアクタンス） | K32: %
D33: （d）Tdo'（開路時定数） | K33: s
D34: （e）Tdo''（開路時定数） | K34: s
D35: （f）慣性定数 | K35: s
D36: 制動巻線 有 ・ 無
B37: 誘導発電機 | D37: （g）x（拘束リアクタンス）
D38: 限流リアクトル | F38: 有 ・ 無 | H38: 限流リアクトル容量
A39: ※（a）、（b）、（c）または、（g）については必ず記載

Sheet 様式３（二次励磁機）
L1: 様式３
L2: 44622
L3: 年 月 日
A4: 発電設備仕様（二次励磁巻線形誘導機）
H6: 発電設備等設置者名
I7: 号発電機 | J7: （既設 ・ 新設 ・ 増設）
A8: １．全般
B9: （１）原動機の種類（風力など）
B10: （２）発電機台数 | H10: [台]
A12: ２．交流発電機
B13: （１）メーカ･型式 | D13: 【ﾒｰｶ】 【型式】
B14: （２）電気方式 | D14: 三相３線式 ・ 単相３線式 ・ 単相２線式
B15: （３）定格容量 | D15: ［kVA］
B16: （４）定格出力 | D16: ［kW］
B17: （５）出力抑制時の最低出力 （火力・バイオマスの場合） | D17: ［kW］
B18: （６）定格電圧 | D18: ［kV］
B19: （７）力率 | C19: 定格 | D19: ［%］ | G19: 運転可能範囲 | I19: 遅れ ［%］～進み ［%］
C20: 調整範囲 | D20: 力率設定範囲： [%]～ [%]
D21: 力率設定ステップ： [%]
B22: （８）定格周波数 | H22: ［Hz］
B23: （９）連続運転可能周波数 | H23: ［Hz］～ ［Hz］
B24: （10）運転可能周波数 （ s） | H24: ［Hz］～ ［Hz］
B25: （11）系統並解列箇所 | H25: 添付 様式５の４ 参照
B26: （12）自動的に同期がとれる機能の有無 | H26: 有 ・ 無
B27: （13）誘導発電機諸定数 （基準容量 kVA）
C28: （a）拘束リアクタンス | G28: (XL) | H28: ［%］
B29: （14）二次励磁装置種類
C30: （a）主回路方式 | G30: 他励式インバータ ・ その他（ ）
G31: 電圧型 ・ 電流型
C32: （b）出力制御方式 | G32: 電圧制御方式 ・ 電流制御方式
G33: ＰＷＭ ・ ＰＡＭ（サイリスタ）
B34: （15）事故時運転継続（ＦＲＴ）要件適用の有無 | G34: 有 ・ 無
B35: （16）高調波電流歪率 | G35: 総合 | H35: ［%］
G36: 各次最大 | H36: 第 次 ［%］
A38: 【留意事項】
B39: ○ | C39: 異なる仕様の発電機がある場合は、本様式を複写し、仕様毎にご記載ください。
B40: ○ | C40: 系統安定度の検討などで、さらに詳細な資料を確認させていただく場合があります。

Sheet 様式５の２
T1: 様式５の２
M3: ※用紙の大きさは、日本工業規格Ａ３サイズまたはＡ４サイズとしてください。
S4: 年 月 日
P5: 発電設備等設置者名
A6: 発 電 機 制 御 系 ブ ロ ッ ク 図
A7: － ガ バ ナ 系 －
